Workbook

Sheet Дашборд и Сводка
A1: ФИНАНСОВЫЙ ПЛАН И КАЛЬКУЛЯТОР ДОХОДНОСТИ НА 1 ГОД
A2: Сравнение стратегий: Форекс (5 торговых дней в неделю / 258 дней в году) vs Криптовалюта (24/7 / 365 дней в году)
A4: [ ПАРАМЕТРЫ СТРАТЕГИИ ] | F4: [ ИТОГИ: ФОРЕКС (5 ДНЕЙ / 258 ДНЕЙ) ] | K4: [ ИТОГИ: КРИПТОВАЛЮТА (24/7 / 365 ДНЕЙ) ]
A5: Начальный депозит ($): | C5: 10 | D5: Стартовый баланс для расчета | F5: Торговых дней в году: | H5: 258 дней (12 мес.) | K5: Торговых дней в году: | M5: 365 дней (12 мес.)
A6: Шаг баланса на 0.01 лота ($): | C6: 100 | D6: До $100 → 0.01, до $200 → 0.02 и т.д. | F6: Начальный депозит: | H6: =$C$5 | K6: Начальный депозит: | M6: =$C$5
A7: Дневная цель (пунктов / pips): | C7: 60 | D7: Целевая прибыль в пунктах за день | F7: Итоговый баланс (1 год): | H7: =F27 | K7: Итоговый баланс (1 год): | M7: =L27
A8: Стоимость 1 пункта (при 1.0 лоте $): | C8: 10 | D8: Стандарт для EURUSD ($10 за пункт) | F8: Чистая прибыль за год: | H8: =E27 | K8: Чистая прибыль за год: | M8: =K27
A9: Максимальный размер лота (Max Lot): | C9: 100 | D9: Лимит брокера на 1 сделку (100.00 лотов) | F9: Пиковый лот (достигнутый): | H9: =D27 | K9: Пиковый лот (достигнутый): | M9: =J27
A10: Базовая прибыль за день (0.01 лота $): | C10: =$C$7*$C$8*0.01 | D10: Прибыль при минимальном лоте ($6.00) | F10: Общая доходность (%): | H10: =G27 | K10: Общая доходность (%): | M10: =M27
A12: [ СВОДНАЯ СРАВНИТЕЛЬНАЯ ТАБЛИЦА ПО МЕСЯЦАМ (12 МЕСЯЦЕВ) ]
A13: Месяц | B13: ФОРЕКС (5 ДНЕЙ В НЕДЕЛЮ) | H13: КРИПТОВАЛЮТА (24/7 - 7 ДНЕЙ В НЕДЕЛЮ) | N13: Разница (Крипто - Форекс)
B14: Дней | C14: Старт ($) | D14: Лот (макс) | E14: Прибыль ($) | F14: Итог ($) | G14: Рост (%) | H14: Дней | I14: Старт ($) | J14: Лот (макс) | K14: Прибыль ($) | L14: Итог ($) | M14: Рост (%)
A15: 1. Январь | B15: 22 | C15: ='Форекс (5 дней)'!D6 | D15: ='Форекс (5 дней)'!E28 | E15: ='Форекс (5 дней)'!G28 | F15: ='Форекс (5 дней)'!H28 | G15: =(F15-C15)/C15 | H15: 31 | I15: ='Криптовалюта (24_7)'!D6 | J15: ='Криптовалюта (24_7)'!E37 | K15: ='Криптовалюта (24_7)'!G37 | L15: ='Криптовалюта (24_7)'!H37 | M15: =(L15-I15)/I15 | N15: =K15-E15
A16: 2. Февраль | B16: 20 | C16: ='Форекс (5 дней)'!D32 | D16: ='Форекс (5 дней)'!E52 | E16: ='Форекс (5 дней)'!G52 | F16: ='Форекс (5 дней)'!H52 | G16: =(F16-C16)/C16 | H16: 28 | I16: ='Криптовалюта (24_7)'!D41 | J16: ='Криптовалюта (24_7)'!E69 | K16: ='Криптовалюта (24_7)'!G69 | L16: ='Криптовалюта (24_7)'!H69 | M16: =(L16-I16)/I16 | N16: =K16-E16
A17: 3. Март | B17: 22 | C17: ='Форекс (5 дней)'!D56 | D17: ='Форекс (5 дней)'!E78 | E17: ='Форекс (5 дней)'!G78 | F17: ='Форекс (5 дней)'!H78 | G17: =(F17-C17)/C17 | H17: 31 | I17: ='Криптовалюта (24_7)'!D73 | J17: ='Криптовалюта (24_7)'!E104 | K17: ='Криптовалюта (24_7)'!G104 | L17: ='Криптовалюта (24_7)'!H104 | M17: =(L17-I17)/I17 | N17: =K17-E17
A18: 4. Апрель | B18: 21 | C18: ='Форекс (5 дней)'!D82 | D18: ='Форекс (5 дней)'!E103 | E18: ='Форекс (5 дней)'!G103 | F18: ='Форекс (5 дней)'!H103 | G18: =(F18-C18)/C18 | H18: 30 | I18: ='Криптовалюта (24_7)'!D108 | J18: ='Криптовалюта (24_7)'!E138 | K18: ='Криптовалюта (24_7)'!G138 | L18: ='Криптовалюта (24_7)'!H138 | M18: =(L18-I18)/I18 | N18: =K18-E18
A19: 5. Май | B19: 22 | C19: ='Форекс (5 дней)'!D107 | D19: ='Форекс (5 дней)'!E129 | E19: ='Форекс (5 дней)'!G129 | F19: ='Форекс (5 дней)'!H129 | G19: =(F19-C19)/C19 | H19: 31 | I19: ='Криптовалюта (24_7)'!D142 | J19: ='Криптовалюта (24_7)'!E173 | K19: ='Криптовалюта (24_7)'!G173 | L19: ='Криптовалюта (24_7)'!H173 | M19: =(L19-I19)/I19 | N19: =K19-E19
A20: 6. Июнь | B20: 21 | C20: ='Форекс (5 дней)'!D133 | D20: ='Форекс (5 дней)'!E154 | E20: ='Форекс (5 дней)'!G154 | F20: ='Форекс (5 дней)'!H154 | G20: =(F20-C20)/C20 | H20: 30 | I20: ='Криптовалюта (24_7)'!D177 | J20: ='Криптовалюта (24_7)'!E207 | K20: ='Криптовалюта (24_7)'!G207 | L20: ='Криптовалюта (24_7)'!H207 | M20: =(L20-I20)/I20 | N20: =K20-E20
A21: 7. Июль | B21: 22 | C21: ='Форекс (5 дней)'!D158 | D21: ='Форекс (5 дней)'!E180 | E21: ='Форекс (5 дней)'!G180 | F21: ='Форекс (5 дней)'!H180 | G21: =(F21-C21)/C21 | H21: 31 | I21: ='Криптовалюта (24_7)'!D211 | J21: ='Криптовалюта (24_7)'!E242 | K21: ='Криптовалюта (24_7)'!G242 | L21: ='Криптовалюта (24_7)'!H242 | M21: =(L21-I21)/I21 | N21: =K21-E21
A22: 8. Август | B22: 22 | C22: ='Форекс (5 дней)'!D184 | D22: ='Форекс (5 дней)'!E206 | E22: ='Форекс (5 дней)'!G206 | F22: ='Форекс (5 дней)'!H206 | G22: =(F22-C22)/C22 | H22: 31 | I22: ='Криптовалюта (24_7)'!D246 | J22: ='Криптовалюта (24_7)'!E277 | K22: ='Криптовалюта (24_7)'!G277 | L22: ='Криптовалюта (24_7)'!H277 | M22: =(L22-I22)/I22 | N22: =K22-E22
A23: 9. Сентябрь | B23: 21 | C23: ='Форекс (5 дней)'!D210 | D23: ='Форекс (5 дней)'!E231 | E23: ='Форекс (5 дней)'!G231 | F23: ='Форекс (5 дней)'!H231 | G23: =(F23-C23)/C23 | H23: 30 | I23: ='Криптовалюта (24_7)'!D281 | J23: ='Криптовалюта (24_7)'!E311 | K23: ='Криптовалюта (24_7)'!G311 | L23: ='Криптовалюта (24_7)'!H311 | M23: =(L23-I23)/I23 | N23: =K23-E23
A24: 10. Октябрь | B24: 22 | C24: ='Форекс (5 дней)'!D235 | D24: ='Форекс (5 дней)'!E257 | E24: ='Форекс (5 дней)'!G257 | F24: ='Форекс (5 дней)'!H257 | G24: =(F24-C24)/C24 | H24: 31 | I24: ='Криптовалюта (24_7)'!D315 | J24: ='Криптовалюта (24_7)'!E346 | K24: ='Криптовалюта (24_7)'!G346 | L24: ='Криптовалюта (24_7)'!H346 | M24: =(L24-I24)/I24 | N24: =K24-E24
A25: 11. Ноябрь | B25: 21 | C25: ='Форекс (5 дней)'!D261 | D25: ='Форекс (5 дней)'!E282 | E25: ='Форекс (5 дней)'!G282 | F25: ='Форекс (5 дней)'!H282 | G25: =(F25-C25)/C25 | H25: 30 | I25: ='Криптовалюта (24_7)'!D350 | J25: ='Криптовалюта (24_7)'!E380 | K25: ='Криптовалюта (24_7)'!G380 | L25: ='Криптовалюта (24_7)'!H380 | M25: =(L25-I25)/I25 | N25: =K25-E25
A26: 12. Декабрь | B26: 22 | C26: ='Форекс (5 дней)'!D286 | D26: ='Форекс (5 дней)'!E308 | E26: ='Форекс (5 дней)'!G308 | F26: ='Форекс (5 дней)'!H308 | G26: =(F26-C26)/C26 | H26: 31 | I26: ='Криптовалюта (24_7)'!D384 | J26: ='Криптовалюта (24_7)'!E415 | K26: ='Криптовалюта (24_7)'!G415 | L26: ='Криптовалюта (24_7)'!H415 | M26: =(L26-I26)/I26 | N26: =K26-E26
A27: ИТОГО ЗА 1 ГОД: | B27: =SUM(B15:B26) | C27: =C15 | D27: =MAX(D15:D26) | E27: =SUM(E15:E26) | F27: =F26 | G27: =(F27-C27)/C27 | H27: =SUM(H15:H26) | I27: =I15 | J27: =MAX(J15:J26) | K27: =SUM(K15:K26) | L27: =L26 | M27: =(L27-I27)/I27 | N27: =K27-E27

Sheet Форекс (5 дней)
A1: ТОРГОВЫЙ ПЛАН НА 1 ГОД: ФОРЕКС (5 ДНЕЙ В НЕДЕЛЮ / 258 ДНЕЙ)
A2: Расчёт сложного процента с шагом 0.01 лота на $100 (Max Lot = 100, 60 пунктов в день)
A4: МЕСЯЦ 1: ЯНВАРЬ (22 торговых дней)
A5: Месяц | B5: День года | C5: День месяца | D5: Начальный депозит ($) | E5: Размер лота | F5: Цель (пунктов) | G5: Прибыль за день ($) | H5: Итоговый баланс ($)
A6: Январь | B6: 1 | C6: 1 | D6: ='Дашборд и Сводка'!$C$5 | E6: =MIN('Дашборд и Сводка'!$C$9, ROUNDUP(D6/'Дашборд и Сводка'!$C$6, 0)*0.01) | F6: ='Дашборд и Сводка'!$C$7 | G6: =E6*F6*'Дашборд и Сводка'!$C$8 | H6: =D6+G6
A7: Январь | B7: 2 | C7: 2 | D7: =H6 | E7: =MIN('Дашборд и Сводка'!$C$9, ROUNDUP(D7/'Дашборд и Сводка'!$C$6, 0)*0.01) | F7: ='Дашборд и Сводка'!$C$7 | G7: =E7*F7*'Дашборд и Сводка'!$C$8 | H7: =D7+G7
A8: Январь | B8: 3 | C8: 3 | D8: =H7 | E8: =MIN('Дашборд и Сводка'!$C$9, ROUNDUP(D8/'Дашборд и Сводка'!$C$6, 0)*0.01) | F8: ='Дашборд и Сводка'!$C$7 | G8: =E8*F8*'Дашборд и Сводка'!$C$8 | H8: =D8+G8
A9: Январь | B9: 4 | C9: 4 | D9: =H8 | E9: =MIN('Дашборд и Сводка'!$C$9, ROUNDUP(D9/'Дашборд и Сводка'!$C$6, 0)*0.01) | F9: ='Дашборд и Сводка'!$C$7 | G9: =E9*F9*'Дашборд и Сводка'!$C$8 | H9: =D9+G9
A10: Январь | B10: 5 | C10: 5 | D10: =H9 | E10: =MIN('Дашборд и Сводка'!$C$9, ROUNDUP(D10/'Дашборд и Сводка'!$C$6, 0)*0.01) | F10: ='Дашборд и Сводка'!$C$7 | G10: =E10*F10*'Дашборд и Сводка'!$C$8 | H10: =D10+G10
A11: Январь | B11: 6 | C11: 6 | D11: =H10 | E11: =MIN('Дашборд и Сводка'!$C$9, ROUNDUP(D11/'Дашборд и Сводка'!$C$6, 0)*0.01) | F11: ='Дашборд и Сводка'!$C$7 | G11: =E11*F11*'Дашборд и Сводка'!$C$8 | H11: =D11+G11
A12: Январь | B12: 7 | C12: 7 | D12: =H11 | E12: =MIN('Дашборд и Сводка'!$C$9, ROUNDUP(D12/'Дашборд и Сводка'!$C$6, 0)*0.01) | F12: ='Дашборд и Сводка'!$C$7 | G12: =E12*F12*'Дашборд и Сводка'!$C$8 | H12: =D12+G12
A13: Январь | B13: 8 | C13: 8 | D13: =H12 | E13: =MIN('Дашборд и Сводка'!$C$9, ROUNDUP(D13/'Дашборд и Сводка'!$C$6, 0)*0.01) | F13: ='Дашборд и Сводка'!$C$7 | G13: =E13*F13*'Дашборд и Сводка'!$C$8 | H13: =D13+G13
A14: Январь | B14: 9 | C14: 9 | D14: =H13 | E14: =MIN('Дашборд и Сводка'!$C$9, ROUNDUP(D14/'Дашборд и Сводка'!$C$6, 0)*0.01) | F14: ='Дашборд и Сводка'!$C$7 | G14: =E14*F14*'Дашборд и Сводка'!$C$8 | H14: =D14+G14
A15: Январь | B15: 10 | C15: 10 | D15: =H14 | E15: =MIN('Дашборд и Сводка'!$C$9, ROUNDUP(D15/'Дашборд и Сводка'!$C$6, 0)*0.01) | F15: ='Дашборд и Сводка'!$C$7 | G15: =E15*F15*'Дашборд и Сводка'!$C$8 | H15: =D15+G15
A16: Январь | B16: 11 | C16: 11 | D16: =H15 | E16: =MIN('Дашборд и Сводка'!$C$9, ROUNDUP(D16/'Дашборд и Сводка'!$C$6, 0)*0.01) | F16: ='Дашборд и Сводка'!$C$7 | G16: =E16*F16*'Дашборд и Сводка'!$C$8 | H16: =D16+G16
A17: Январь | B17: 12 | C17: 12 | D17: =H16 | E17: =MIN('Дашборд и Сводка'!$C$9, ROUNDUP(D17/'Дашборд и Сводка'!$C$6, 0)*0.01) | F17: ='Дашборд и Сводка'!$C$7 | G17: =E17*F17*'Дашборд и Сводка'!$C$8 | H17: =D17+G17
A18: Январь | B18: 13 | C18: 13 | D18: =H17 | E18: =MIN('Дашборд и Сводка'!$C$9, ROUNDUP(D18/'Дашборд и Сводка'!$C$6, 0)*0.01) | F18: ='Дашборд и Сводка'!$C$7 | G18: =E18*F18*'Дашборд и Сводка'!$C$8 | H18: =D18+G18
... A27: Январь | B27: 22 | C27: 22 | D27: =H26 | E27: =MIN('Дашборд и Сводка'!$C$9, ROUNDUP(D27/'Дашборд и Сводка'!$C$6, 0)*0.01) | F27: ='Дашборд и Сводка'!$C$7 | G27: =E27*F27*'Дашборд и Сводка'!$C$8 | H27: =D27+G27
A28: ИТОГО ЗА ЯНВАРЬ: | D28: =D6 | E28: =MAX(E6:E27) | F28: ='Дашборд и Сводка'!$C$7 | G28: =SUM(G6:G27) | H28: =H27
A30: МЕСЯЦ 2: ФЕВРАЛЬ (20 торговых дней)
A31: Месяц | B31: День года | C31: День месяца | D31: Начальный депозит ($) | E31: Размер лота | F31: Цель (пунктов) | G31: Прибыль за день ($) | H31: Итоговый баланс ($)
A32: Февраль | B32: 23 | C32: 1 | D32: =H27 | E32: =MIN('Дашборд и Сводка'!$C$9, ROUNDUP(D32/'Дашборд и Сводка'!$C$6, 0)*0.01) | F32: ='Дашборд и Сводка'!$C$7 | G32: =E32*F32*'Дашборд и Сводка'!$C$8 | H32: =D32+G32
A33: Февраль | B33: 24 | C33: 2 | D33: =H32 | E33: =MIN('Дашборд и Сводка'!$C$9, ROUNDUP(D33/'Дашборд и Сводка'!$C$6, 0)*0.01) | F33: ='Дашборд и Сводка'!$C$7 | G33: =E33*F33*'Дашборд и Сводка'!$C$8 | H33: =D33+G33
A34: Февраль | B34: 25 | C34: 3 | D34: =H33 | E34: =MIN('Дашборд и Сводка'!$C$9, ROUNDUP(D34/'Дашборд и Сводка'!$C$6, 0)*0.01) | F34: ='Дашборд и Сводка'!$C$7 | G34: =E34*F34*'Дашборд и Сводка'!$C$8 | H34: =D34+G34
A35: Февраль | B35: 26 | C35: 4 | D35: =H34 | E35: =MIN('Дашборд и Сводка'!$C$9, ROUNDUP(D35/'Дашборд и Сводка'!$C$6, 0)*0.01) | F35: ='Дашборд и Сводка'!$C$7 | G35: =E35*F35*'Дашборд и Сводка'!$C$8 | H35: =D35+G35
A36: Февраль | B36: 27 | C36: 5 | D36: =H35 | E36: =MIN('Дашборд и Сводка'!$C$9, ROUNDUP(D36/'Дашборд и Сводка'!$C$6, 0)*0.01) | F36: ='Дашборд и Сводка'!$C$7 | G36: =E36*F36*'Дашборд и Сводка'!$C$8 | H36: =D36+G36
A37: Февраль | B37: 28 | C37: 6 | D37: =H36 | E37: =MIN('Дашборд и Сводка'!$C$9, ROUNDUP(D37/'Дашборд и Сводка'!$C$6, 0)*0.01) | F37: ='Дашборд и Сводка'!$C$7 | G37: =E37*F37*'Дашборд и Сводка'!$C$8 | H37: =D37+G37
A38: Февраль | B38: 29 | C38: 7 | D38: =H37 | E38: =MIN('Дашборд и Сводка'!$C$9, ROUNDUP(D38/'Дашборд и Сводка'!$C$6, 0)*0.01) | F38: ='Дашборд и Сводка'!$C$7 | G38: =E38*F38*'Дашборд и Сводка'!$C$8 | H38: =D38+G38
A39: Февраль | B39: 30 | C39: 8 | D39: =H38 | E39: =MIN('Дашборд и Сводка'!$C$9, ROUNDUP(D39/'Дашборд и Сводка'!$C$6, 0)*0.01) | F39: ='Дашборд и Сводка'!$C$7 | G39: =E39*F39*'Дашборд и Сводка'!$C$8 | H39: =D39+G39
A40: Февраль | B40: 31 | C40: 9 | D40: =H39 | E40: =MIN('Дашборд и Сводка'!$C$9, ROUNDUP(D40/'Дашборд и Сводка'!$C$6, 0)*0.01) | F40: ='Дашборд и Сводка'!$C$7 | G40: =E40*F40*'Дашборд и Сводка'!$C$8 | H40: =D40+G40
A41: Февраль | B41: 32 | C41: 10 | D41: =H40 | E41: =MIN('Дашборд и Сводка'!$C$9, ROUNDUP(D41/'Дашборд и Сводка'!$C$6, 0)*0.01) | F41: ='Дашборд и Сводка'!$C$7 | G41: =E41*F41*'Дашборд и Сводка'!$C$8 | H41: =D41+G41
A42: Февраль | B42: 33 | C42: 11 | D42: =H41 | E42: =MIN('Дашборд и Сводка'!$C$9, ROUNDUP(D42/'Дашборд и Сводка'!$C$6, 0)*0.01) | F42: ='Дашборд и Сводка'!$C$7 | G42: =E42*F42*'Дашборд и Сводка'!$C$8 | H42: =D42+G42
A43: Февраль | B43: 34 | C43: 12 | D43: =H42 | E43: =MIN('Дашборд и Сводка'!$C$9, ROUNDUP(D43/'Дашборд и Сводка'!$C$6, 0)*0.01) | F43: ='Дашборд и Сводка'!$C$7 | G43: =E43*F43*'Дашборд и Сводка'!$C$8 | H43: =D43+G43
A44: Февраль | B44: 35 | C44: 13 | D44: =H43 | E44: =MIN('Дашборд и Сводка'!$C$9, ROUNDUP(D44/'Дашборд и Сводка'!$C$6, 0)*0.01) | F44: ='Дашборд и Сводка'!$C$7 | G44: =E44*F44*'Дашборд и Сводка'!$C$8 | H44: =D44+G44
... A51: Февраль | B51: 42 | C51: 20 | D51: =H50 | E51: =MIN('Дашборд и Сводка'!$C$9, ROUNDUP(D51/'Дашборд и Сводка'!$C$6, 0)*0.01) | F51: ='Дашборд и Сводка'!$C$7 | G51: =E51*F51*'Дашборд и Сводка'!$C$8 | H51: =D51+G51
A52: ИТОГО ЗА ФЕВРАЛЬ: | D52: =D32 | E52: =MAX(E32:E51) | F52: ='Дашборд и Сводка'!$C$7 | G52: =SUM(G32:G51) | H52: =H51
A54: МЕСЯЦ 3: МАРТ (22 торговых дней)
A55: Месяц | B55: День года | C55: День месяца | D55: Начальный депозит ($) | E55: Размер лота | F55: Цель (пунктов) | G55: Прибыль за день ($) | H55: Итоговый баланс ($)
A56: Март | B56: 43 | C56: 1 | D56: =H51 | E56: =MIN('Дашборд и Сводка'!$C$9, ROUNDUP(D56/'Дашборд и Сводка'!$C$6, 0)*0.01) | F56: ='Дашборд и Сводка'!$C$7 | G56: =E56*F56*'Дашборд и Сводка'!$C$8 | H56: =D56+G56
A57: Март | B57: 44 | C57: 2 | D57: =H56 | E57: =MIN('Дашборд и Сводка'!$C$9, ROUNDUP(D57/'Дашборд и Сводка'!$C$6, 0)*0.01) | F57: ='Дашборд и Сводка'!$C$7 | G57: =E57*F57*'Дашборд и Сводка'!$C$8 | H57: =D57+G57
...

Sheet Криптовалюта (24_7)
A1: ТОРГОВЫЙ ПЛАН НА 1 ГОД: КРИПТОВАЛЮТА (24/7 БЕЗ ВЫХОДНЫХ / 365 ДНЕЙ)
A2: Расчёт сложного процента при непрерывной торговле 7 дней в неделю (Max Lot = 100)
A4: МЕСЯЦ 1: ЯНВАРЬ (31 торговых дней)
A5: Месяц | B5: День года | C5: День месяца | D5: Начальный депозит ($) | E5: Размер лота | F5: Цель (пунктов) | G5: Прибыль за день ($) | H5: Итоговый баланс ($)
A6: Январь | B6: 1 | C6: 1 | D6: ='Дашборд и Сводка'!$C$5 | E6: =MIN('Дашборд и Сводка'!$C$9, ROUNDUP(D6/'Дашборд и Сводка'!$C$6, 0)*0.01) | F6: ='Дашборд и Сводка'!$C$7 | G6: =E6*F6*'Дашборд и Сводка'!$C$8 | H6: =D6+G6
A7: Январь | B7: 2 | C7: 2 | D7: =H6 | E7: =MIN('Дашборд и Сводка'!$C$9, ROUNDUP(D7/'Дашборд и Сводка'!$C$6, 0)*0.01) | F7: ='Дашборд и Сводка'!$C$7 | G7: =E7*F7*'Дашборд и Сводка'!$C$8 | H7: =D7+G7
A8: Январь | B8: 3 | C8: 3 | D8: =H7 | E8: =MIN('Дашборд и Сводка'!$C$9, ROUNDUP(D8/'Дашборд и Сводка'!$C$6, 0)*0.01) | F8: ='Дашборд и Сводка'!$C$7 | G8: =E8*F8*'Дашборд и Сводка'!$C$8 | H8: =D8+G8
A9: Январь | B9: 4 | C9: 4 | D9: =H8 | E9: =MIN('Дашборд и Сводка'!$C$9, ROUNDUP(D9/'Дашборд и Сводка'!$C$6, 0)*0.01) | F9: ='Дашборд и Сводка'!$C$7 | G9: =E9*F9*'Дашборд и Сводка'!$C$8 | H9: =D9+G9
A10: Январь | B10: 5 | C10: 5 | D10: =H9 | E10: =MIN('Дашборд и Сводка'!$C$9, ROUNDUP(D10/'Дашборд и Сводка'!$C$6, 0)*0.01) | F10: ='Дашборд и Сводка'!$C$7 | G10: =E10*F10*'Дашборд и Сводка'!$C$8 | H10: =D10+G10
A11: Январь | B11: 6 | C11: 6 | D11: =H10 | E11: =MIN('Дашборд и Сводка'!$C$9, ROUNDUP(D11/'Дашборд и Сводка'!$C$6, 0)*0.01) | F11: ='Дашборд и Сводка'!$C$7 | G11: =E11*F11*'Дашборд и Сводка'!$C$8 | H11: =D11+G11
A12: Январь | B12: 7 | C12: 7 | D12: =H11 | E12: =MIN('Дашборд и Сводка'!$C$9, ROUNDUP(D12/'Дашборд и Сводка'!$C$6, 0)*0.01) | F12: ='Дашборд и Сводка'!$C$7 | G12: =E12*F12*'Дашборд и Сводка'!$C$8 | H12: =D12+G12
A13: Январь | B13: 8 | C13: 8 | D13: =H12 | E13: =MIN('Дашборд и Сводка'!$C$9, ROUNDUP(D13/'Дашборд и Сводка'!$C$6, 0)*0.01) | F13: ='Дашборд и Сводка'!$C$7 | G13: =E13*F13*'Дашборд и Сводка'!$C$8 | H13: =D13+G13
A14: Январь | B14: 9 | C14: 9 | D14: =H13 | E14: =MIN('Дашборд и Сводка'!$C$9, ROUNDUP(D14/'Дашборд и Сводка'!$C$6, 0)*0.01) | F14: ='Дашборд и Сводка'!$C$7 | G14: =E14*F14*'Дашборд и Сводка'!$C$8 | H14: =D14+G14
A15: Январь | B15: 10 | C15: 10 | D15: =H14 | E15: =MIN('Дашборд и Сводка'!$C$9, ROUNDUP(D15/'Дашборд и Сводка'!$C$6, 0)*0.01) | F15: ='Дашборд и Сводка'!$C$7 | G15: =E15*F15*'Дашборд и Сводка'!$C$8 | H15: =D15+G15
A16: Январь | B16: 11 | C16: 11 | D16: =H15 | E16: =MIN('Дашборд и Сводка'!$C$9, ROUNDUP(D16/'Дашборд и Сводка'!$C$6, 0)*0.01) | F16: ='Дашборд и Сводка'!$C$7 | G16: =E16*F16*'Дашборд и Сводка'!$C$8 | H16: =D16+G16
A17: Январь | B17: 12 | C17: 12 | D17: =H16 | E17: =MIN('Дашборд и Сводка'!$C$9, ROUNDUP(D17/'Дашборд и Сводка'!$C$6, 0)*0.01) | F17: ='Дашборд и Сводка'!$C$7 | G17: =E17*F17*'Дашборд и Сводка'!$C$8 | H17: =D17+G17
A18: Январь | B18: 13 | C18: 13 | D18: =H17 | E18: =MIN('Дашборд и Сводка'!$C$9, ROUNDUP(D18/'Дашборд и Сводка'!$C$6, 0)*0.01) | F18: ='Дашборд и Сводка'!$C$7 | G18: =E18*F18*'Дашборд и Сводка'!$C$8 | H18: =D18+G18
... A36: Январь | B36: 31 | C36: 31 | D36: =H35 | E36: =MIN('Дашборд и Сводка'!$C$9, ROUNDUP(D36/'Дашборд и Сводка'!$C$6, 0)*0.01) | F36: ='Дашборд и Сводка'!$C$7 | G36: =E36*F36*'Дашборд и Сводка'!$C$8 | H36: =D36+G36
A37: ИТОГО ЗА ЯНВАРЬ: | D37: =D6 | E37: =MAX(E6:E36) | F37: ='Дашборд и Сводка'!$C$7 | G37: =SUM(G6:G36) | H37: =H36
A39: МЕСЯЦ 2: ФЕВРАЛЬ (28 торговых дней)
A40: Месяц | B40: День года | C40: День месяца | D40: Начальный депозит ($) | E40: Размер лота | F40: Цель (пунктов) | G40: Прибыль за день ($) | H40: Итоговый баланс ($)
A41: Февраль | B41: 32 | C41: 1 | D41: =H36 | E41: =MIN('Дашборд и Сводка'!$C$9, ROUNDUP(D41/'Дашборд и Сводка'!$C$6, 0)*0.01) | F41: ='Дашборд и Сводка'!$C$7 | G41: =E41*F41*'Дашборд и Сводка'!$C$8 | H41: =D41+G41
A42: Февраль | B42: 33 | C42: 2 | D42: =H41 | E42: =MIN('Дашборд и Сводка'!$C$9, ROUNDUP(D42/'Дашборд и Сводка'!$C$6, 0)*0.01) | F42: ='Дашборд и Сводка'!$C$7 | G42: =E42*F42*'Дашборд и Сводка'!$C$8 | H42: =D42+G42
A43: Февраль | B43: 34 | C43: 3 | D43: =H42 | E43: =MIN('Дашборд и Сводка'!$C$9, ROUNDUP(D43/'Дашборд и Сводка'!$C$6, 0)*0.01) | F43: ='Дашборд и Сводка'!$C$7 | G43: =E43*F43*'Дашборд и Сводка'!$C$8 | H43: =D43+G43
A44: Февраль | B44: 35 | C44: 4 | D44: =H43 | E44: =MIN('Дашборд и Сводка'!$C$9, ROUNDUP(D44/'Дашборд и Сводка'!$C$6, 0)*0.01) | F44: ='Дашборд и Сводка'!$C$7 | G44: =E44*F44*'Дашборд и Сводка'!$C$8 | H44: =D44+G44
A45: Февраль | B45: 36 | C45: 5 | D45: =H44 | E45: =MIN('Дашборд и Сводка'!$C$9, ROUNDUP(D45/'Дашборд и Сводка'!$C$6, 0)*0.01) | F45: ='Дашборд и Сводка'!$C$7 | G45: =E45*F45*'Дашборд и Сводка'!$C$8 | H45: =D45+G45
A46: Февраль | B46: 37 | C46: 6 | D46: =H45 | E46: =MIN('Дашборд и Сводка'!$C$9, ROUNDUP(D46/'Дашборд и Сводка'!$C$6, 0)*0.01) | F46: ='Дашборд и Сводка'!$C$7 | G46: =E46*F46*'Дашборд и Сводка'!$C$8 | H46: =D46+G46
A47: Февраль | B47: 38 | C47: 7 | D47: =H46 | E47: =MIN('Дашборд и Сводка'!$C$9, ROUNDUP(D47/'Дашборд и Сводка'!$C$6, 0)*0.01) | F47: ='Дашборд и Сводка'!$C$7 | G47: =E47*F47*'Дашборд и Сводка'!$C$8 | H47: =D47+G47
A48: Февраль | B48: 39 | C48: 8 | D48: =H47 | E48: =MIN('Дашборд и Сводка'!$C$9, ROUNDUP(D48/'Дашборд и Сводка'!$C$6, 0)*0.01) | F48: ='Дашборд и Сводка'!$C$7 | G48: =E48*F48*'Дашборд и Сводка'!$C$8 | H48: =D48+G48
A49: Февраль | B49: 40 | C49: 9 | D49: =H48 | E49: =MIN('Дашборд и Сводка'!$C$9, ROUNDUP(D49/'Дашборд и Сводка'!$C$6, 0)*0.01) | F49: ='Дашборд и Сводка'!$C$7 | G49: =E49*F49*'Дашборд и Сводка'!$C$8 | H49: =D49+G49
A50: Февраль | B50: 41 | C50: 10 | D50: =H49 | E50: =MIN('Дашборд и Сводка'!$C$9, ROUNDUP(D50/'Дашборд и Сводка'!$C$6, 0)*0.01) | F50: ='Дашборд и Сводка'!$C$7 | G50: =E50*F50*'Дашборд и Сводка'!$C$8 | H50: =D50+G50
A51: Февраль | B51: 42 | C51: 11 | D51: =H50 | E51: =MIN('Дашборд и Сводка'!$C$9, ROUNDUP(D51/'Дашборд и Сводка'!$C$6, 0)*0.01) | F51: ='Дашборд и Сводка'!$C$7 | G51: =E51*F51*'Дашборд и Сводка'!$C$8 | H51: =D51+G51
A52: Февраль | B52: 43 | C52: 12 | D52: =H51 | E52: =MIN('Дашборд и Сводка'!$C$9, ROUNDUP(D52/'Дашборд и Сводка'!$C$6, 0)*0.01) | F52: ='Дашборд и Сводка'!$C$7 | G52: =E52*F52*'Дашборд и Сводка'!$C$8 | H52: =D52+G52
A53: Февраль | B53: 44 | C53: 13 | D53: =H52 | E53: =MIN('Дашборд и Сводка'!$C$9, ROUNDUP(D53/'Дашборд и Сводка'!$C$6, 0)*0.01) | F53: ='Дашборд и Сводка'!$C$7 | G53: =E53*F53*'Дашборд и Сводка'!$C$8 | H53: =D53+G53
... A68: Февраль | B68: 59 | C68: 28 | D68: =H67 | E68: =MIN('Дашборд и Сводка'!$C$9, ROUNDUP(D68/'Дашборд и Сводка'!$C$6, 0)*0.01) | F68: ='Дашборд и Сводка'!$C$7 | G68: =E68*F68*'Дашборд и Сводка'!$C$8 | H68: =D68+G68
A69: ИТОГО ЗА ФЕВРАЛЬ: | D69: =D41 | E69: =MAX(E41:E68) | F69: ='Дашборд и Сводка'!$C$7 | G69: =SUM(G41:G68) | H69: =H68
A71: МЕСЯЦ 3: МАРТ (31 торговых дней)
A72: Месяц | B72: День года | C72: День месяца | D72: Начальный депозит ($) | E72: Размер лота | F72: Цель (пунктов) | G72: Прибыль за день ($) | H72: Итоговый баланс ($)
A73: Март | B73: 60 | C73: 1 | D73: =H68 | E73: =MIN('Дашборд и Сводка'!$C$9, ROUNDUP(D73/'Дашборд и Сводка'!$C$6, 0)*0.01) | F73: ='Дашборд и Сводка'!$C$7 | G73: =E73*F73*'Дашборд и Сводка'!$C$8 | H73: =D73+G73
A74: Март | B74: 61 | C74: 2 | D74: =H73 | E74: =MIN('Дашборд и Сводка'!$C$9, ROUNDUP(D74/'Дашборд и Сводка'!$C$6, 0)*0.01) | F74: ='Дашборд и Сводка'!$C$7 | G74: =E74*F74*'Дашборд и Сводка'!$C$8 | H74: =D74+G74
...
